2023-04-21 17:14:09,716 ERROR: Exception on /reset_password_request [POST] [in C:\VSCode\microblog\venv\Lib\site-packages\flask\app.py:1744]
Traceback (most recent call last):
  File "C:\VSCode\microblog\venv\Lib\site-packages\flask\app.py", line 2528, in wsgi_app
    response = self.full_dispatch_request()
               ^^^^^^^^^^^^^^^^^^^^^^^^^^^^
  File "C:\VSCode\microblog\venv\Lib\site-packages\flask\app.py", line 1825, in full_dispatch_request
    rv = self.handle_user_exception(e)
         ^^^^^^^^^^^^^^^^^^^^^^^^^^^^^
  File "C:\VSCode\microblog\venv\Lib\site-packages\flask\app.py", line 1823, in full_dispatch_request
    rv = self.dispatch_request()
         ^^^^^^^^^^^^^^^^^^^^^^^
  File "C:\VSCode\microblog\venv\Lib\site-packages\flask\app.py", line 1799, in dispatch_request
    return self.ensure_sync(self.view_functions[rule.endpoint])(**view_args)
           ^^^^^^^^^^^^^^^^^^^^^^^^^^^^^^^^^^^^^^^^^^^^^^^^^^^^^^^^^^^^^^^^^
  File "C:\VSCode\microblog\app\routes.py", line 157, in reset_password_request
    send_password_reset_email(user)
  File "C:\VSCode\microblog\app\email.py", line 14, in send_password_reset_email
    send_email('[microblog] Reset Your Password', sender=app.config['ADMINS'][0], recipients=[user.email], text_body=render_template('email/reset_password.txt', user=user, token=token),
  File "C:\VSCode\microblog\app\email.py", line 10, in send_email
    mail.send(msg)
  File "C:\VSCode\microblog\venv\Lib\site-packages\flask_mail.py", line 491, in send
    with self.connect() as connection:
  File "C:\VSCode\microblog\venv\Lib\site-packages\flask_mail.py", line 144, in __enter__
    self.host = self.configure_host()
                ^^^^^^^^^^^^^^^^^^^^^
  File "C:\VSCode\microblog\venv\Lib\site-packages\flask_mail.py", line 158, in configure_host
    host = smtplib.SMTP(self.mail.server, self.mail.port)
           ^^^^^^^^^^^^^^^^^^^^^^^^^^^^^^^^^^^^^^^^^^^^^^
  File "C:\Users\Sean Lovins\AppData\Local\Programs\Python\Python311\Lib\smtplib.py", line 255, in __init__
    (code, msg) = self.connect(host, port)
                  ^^^^^^^^^^^^^^^^^^^^^^^^
  File "C:\Users\Sean Lovins\AppData\Local\Programs\Python\Python311\Lib\smtplib.py", line 341, in connect
    self.sock = self._get_socket(host, port, self.timeout)
                ^^^^^^^^^^^^^^^^^^^^^^^^^^^^^^^^^^^^^^^^^^
  File "C:\Users\Sean Lovins\AppData\Local\Programs\Python\Python311\Lib\smtplib.py", line 312, in _get_socket
    return socket.create_connection((host, port), timeout,
           ^^^^^^^^^^^^^^^^^^^^^^^^^^^^^^^^^^^^^^^^^^^^^^^
  File "C:\Users\Sean Lovins\AppData\Local\Programs\Python\Python311\Lib\socket.py", line 851, in create_connection
    raise exceptions[0]
  File "C:\Users\Sean Lovins\AppData\Local\Programs\Python\Python311\Lib\socket.py", line 836, in create_connection
    sock.connect(sa)
ConnectionRefusedError: [WinError 10061] No connection could be made because the target machine actively refused it
2023-04-21 17:14:48,926 ERROR: Exception on /reset_password_request [POST] [in C:\VSCode\microblog\venv\Lib\site-packages\flask\app.py:1744]
Traceback (most recent call last):
  File "C:\VSCode\microblog\venv\Lib\site-packages\flask\app.py", line 2528, in wsgi_app
    response = self.full_dispatch_request()
               ^^^^^^^^^^^^^^^^^^^^^^^^^^^^
  File "C:\VSCode\microblog\venv\Lib\site-packages\flask\app.py", line 1825, in full_dispatch_request
    rv = self.handle_user_exception(e)
         ^^^^^^^^^^^^^^^^^^^^^^^^^^^^^
  File "C:\VSCode\microblog\venv\Lib\site-packages\flask\app.py", line 1823, in full_dispatch_request
    rv = self.dispatch_request()
         ^^^^^^^^^^^^^^^^^^^^^^^
  File "C:\VSCode\microblog\venv\Lib\site-packages\flask\app.py", line 1799, in dispatch_request
    return self.ensure_sync(self.view_functions[rule.endpoint])(**view_args)
           ^^^^^^^^^^^^^^^^^^^^^^^^^^^^^^^^^^^^^^^^^^^^^^^^^^^^^^^^^^^^^^^^^
  File "C:\VSCode\microblog\app\routes.py", line 157, in reset_password_request
    send_password_reset_email(user)
  File "C:\VSCode\microblog\app\email.py", line 14, in send_password_reset_email
    send_email('[microblog] Reset Your Password', sender=app.config['ADMINS'][0], recipients=[user.email], text_body=render_template('email/reset_password.txt', user=user, token=token),
  File "C:\VSCode\microblog\app\email.py", line 10, in send_email
    mail.send(msg)
  File "C:\VSCode\microblog\venv\Lib\site-packages\flask_mail.py", line 491, in send
    with self.connect() as connection:
  File "C:\VSCode\microblog\venv\Lib\site-packages\flask_mail.py", line 144, in __enter__
    self.host = self.configure_host()
                ^^^^^^^^^^^^^^^^^^^^^
  File "C:\VSCode\microblog\venv\Lib\site-packages\flask_mail.py", line 158, in configure_host
    host = smtplib.SMTP(self.mail.server, self.mail.port)
           ^^^^^^^^^^^^^^^^^^^^^^^^^^^^^^^^^^^^^^^^^^^^^^
  File "C:\Users\Sean Lovins\AppData\Local\Programs\Python\Python311\Lib\smtplib.py", line 255, in __init__
    (code, msg) = self.connect(host, port)
                  ^^^^^^^^^^^^^^^^^^^^^^^^
  File "C:\Users\Sean Lovins\AppData\Local\Programs\Python\Python311\Lib\smtplib.py", line 341, in connect
    self.sock = self._get_socket(host, port, self.timeout)
                ^^^^^^^^^^^^^^^^^^^^^^^^^^^^^^^^^^^^^^^^^^
  File "C:\Users\Sean Lovins\AppData\Local\Programs\Python\Python311\Lib\smtplib.py", line 312, in _get_socket
    return socket.create_connection((host, port), timeout,
           ^^^^^^^^^^^^^^^^^^^^^^^^^^^^^^^^^^^^^^^^^^^^^^^
  File "C:\Users\Sean Lovins\AppData\Local\Programs\Python\Python311\Lib\socket.py", line 851, in create_connection
    raise exceptions[0]
  File "C:\Users\Sean Lovins\AppData\Local\Programs\Python\Python311\Lib\socket.py", line 836, in create_connection
    sock.connect(sa)
ConnectionRefusedError: [WinError 10061] No connection could be made because the target machine actively refused it
2023-04-21 17:24:06,662 INFO: Microblog startup [in C:\VSCode\microblog\app\__init__.py:45]
2023-04-22 20:34:01,706 INFO: Microblog startup [in C:\VSCode\microblog\app\__init__.py:45]
2023-04-22 21:44:27,616 INFO: Microblog startup [in C:\VSCode\microblog\app\__init__.py:47]
2023-04-22 21:44:32,993 ERROR: Exception on / [GET] [in C:\VSCode\microblog\venv\Lib\site-packages\flask\app.py:1744]
Traceback (most recent call last):
  File "C:\VSCode\microblog\venv\Lib\site-packages\flask\app.py", line 2528, in wsgi_app
    response = self.full_dispatch_request()
               ^^^^^^^^^^^^^^^^^^^^^^^^^^^^
  File "C:\VSCode\microblog\venv\Lib\site-packages\flask\app.py", line 1825, in full_dispatch_request
    rv = self.handle_user_exception(e)
         ^^^^^^^^^^^^^^^^^^^^^^^^^^^^^
  File "C:\VSCode\microblog\venv\Lib\site-packages\flask\app.py", line 1823, in full_dispatch_request
    rv = self.dispatch_request()
         ^^^^^^^^^^^^^^^^^^^^^^^
  File "C:\VSCode\microblog\venv\Lib\site-packages\flask\app.py", line 1799, in dispatch_request
    return self.ensure_sync(self.view_functions[rule.endpoint])(**view_args)
           ^^^^^^^^^^^^^^^^^^^^^^^^^^^^^^^^^^^^^^^^^^^^^^^^^^^^^^^^^^^^^^^^^
  File "C:\VSCode\microblog\venv\Lib\site-packages\flask_login\utils.py", line 290, in decorated_view
    return current_app.ensure_sync(func)(*args, **kwargs)
           ^^^^^^^^^^^^^^^^^^^^^^^^^^^^^^^^^^^^^^^^^^^^^^
  File "C:\VSCode\microblog\app\routes.py", line 34, in index
    return render_template('index.html', title='Home Page', form=form, posts=posts.items, next_url=next_url, prev_url=prev_url)
           ^^^^^^^^^^^^^^^^^^^^^^^^^^^^^^^^^^^^^^^^^^^^^^^^^^^^^^^^^^^^^^^^^^^^^^^^^^^^^^^^^^^^^^^^^^^^^^^^^^^^^^^^^^^^^^^^^^^^
  File "C:\VSCode\microblog\venv\Lib\site-packages\flask\templating.py", line 147, in render_template
    return _render(app, template, context)
           ^^^^^^^^^^^^^^^^^^^^^^^^^^^^^^^
  File "C:\VSCode\microblog\venv\Lib\site-packages\flask\templating.py", line 130, in _render
    rv = template.render(context)
         ^^^^^^^^^^^^^^^^^^^^^^^^
  File "C:\VSCode\microblog\venv\Lib\site-packages\jinja2\environment.py", line 1301, in render
    self.environment.handle_exception()
  File "C:\VSCode\microblog\venv\Lib\site-packages\jinja2\environment.py", line 936, in handle_exception
    raise rewrite_traceback_stack(source=source)
  File "C:\VSCode\microblog\app\templates\index.html", line 1, in top-level template code
    {% extends "base.html" %}
  File "C:\VSCode\microblog\venv\Lib\site-packages\jinja2\environment.py", line 936, in handle_exception
    raise rewrite_traceback_stack(source=source)
  File "C:\VSCode\microblog\app\templates\base.html", line 48, in template
    {% block content %}{% endblock %}
    ^^^^^^^^^^^^^^^^^^^^^^^^^
jinja2.exceptions.TemplateAssertionError: block 'content' defined twice
2023-04-22 21:45:13,134 INFO: Microblog startup [in C:\VSCode\microblog\app\__init__.py:47]
