2023-04-18 01:02:02,687 ERROR: Exception on /index [GET] [in C:\VSCode\microblog\venv\Lib\site-packages\flask\app.py:1744]
Traceback (most recent call last):
  File "C:\VSCode\microblog\venv\Lib\site-packages\flask\app.py", line 2528, in wsgi_app
    response = self.full_dispatch_request()
               ^^^^^^^^^^^^^^^^^^^^^^^^^^^^
  File "C:\VSCode\microblog\venv\Lib\site-packages\flask\app.py", line 1825, in full_dispatch_request
    rv = self.handle_user_exception(e)
         ^^^^^^^^^^^^^^^^^^^^^^^^^^^^^
  File "C:\VSCode\microblog\venv\Lib\site-packages\flask\app.py", line 1823, in full_dispatch_request
    rv = self.dispatch_request()
         ^^^^^^^^^^^^^^^^^^^^^^^
  File "C:\VSCode\microblog\venv\Lib\site-packages\flask\app.py", line 1799, in dispatch_request
    return self.ensure_sync(self.view_functions[rule.endpoint])(**view_args)
           ^^^^^^^^^^^^^^^^^^^^^^^^^^^^^^^^^^^^^^^^^^^^^^^^^^^^^^^^^^^^^^^^^
  File "C:\VSCode\microblog\venv\Lib\site-packages\flask_login\utils.py", line 290, in decorated_view
    return current_app.ensure_sync(func)(*args, **kwargs)
           ^^^^^^^^^^^^^^^^^^^^^^^^^^^^^^^^^^^^^^^^^^^^^^
  File "C:\VSCode\microblog\app\routes.py", line 36, in index
    return render_template('index.html', title='Home Page', form=form, posts=posts)
           ^^^^^^^^^^^^^^^^^^^^^^^^^^^^^^^^^^^^^^^^^^^^^^^^^^^^^^^^^^^^^^^^^^^^^^^^
  File "C:\VSCode\microblog\venv\Lib\site-packages\flask\templating.py", line 147, in render_template
    return _render(app, template, context)
           ^^^^^^^^^^^^^^^^^^^^^^^^^^^^^^^
  File "C:\VSCode\microblog\venv\Lib\site-packages\flask\templating.py", line 130, in _render
    rv = template.render(context)
         ^^^^^^^^^^^^^^^^^^^^^^^^
  File "C:\VSCode\microblog\venv\Lib\site-packages\jinja2\environment.py", line 1301, in render
    self.environment.handle_exception()
  File "C:\VSCode\microblog\venv\Lib\site-packages\jinja2\environment.py", line 936, in handle_exception
    raise rewrite_traceback_stack(source=source)
  File "C:\VSCode\microblog\app\templates\index.html", line 1, in top-level template code
    {% extends "base.html" %}
  File "C:\VSCode\microblog\app\templates\base.html", line 35, in top-level template code
    {% block content %}{% endblock %}
    ^^^^^^^^^^^^^^^^^^^^^^^^^
  File "C:\VSCode\microblog\app\templates\index.html", line 19, in block 'content'
    {% include '_post.html' %}
    ^^^^^^^^^^^^^^^^^^^^^^^^^
  File "C:\VSCode\microblog\app\templates\_post.html", line 3, in top-level template code
    <td><img src="{{ post.author.avatar(36) }}"></td>
    ^^^^^^^^^^^^^^^^^^^^^^^^^
  File "C:\VSCode\microblog\venv\Lib\site-packages\jinja2\utils.py", line 83, in from_obj
    if hasattr(obj, "jinja_pass_arg"):
       ^^^^^^^^^^^^^^^^^^^^^^^^^^^^^^
jinja2.exceptions.UndefinedError: 'dict object' has no attribute 'avatar'
2023-04-18 01:03:00,466 INFO: Microblog startup [in C:\VSCode\microblog\app\__init__.py:43]
2023-04-19 12:20:45,849 INFO: Microblog startup [in C:\VSCode\microblog\app\__init__.py:43]
2023-04-19 12:21:02,449 ERROR: Exception on /explore [GET] [in C:\VSCode\microblog\venv\Lib\site-packages\flask\app.py:1744]
Traceback (most recent call last):
  File "C:\VSCode\microblog\venv\Lib\site-packages\flask\app.py", line 2528, in wsgi_app
    response = self.full_dispatch_request()
               ^^^^^^^^^^^^^^^^^^^^^^^^^^^^
  File "C:\VSCode\microblog\venv\Lib\site-packages\flask\app.py", line 1825, in full_dispatch_request
    rv = self.handle_user_exception(e)
         ^^^^^^^^^^^^^^^^^^^^^^^^^^^^^
  File "C:\VSCode\microblog\venv\Lib\site-packages\flask\app.py", line 1823, in full_dispatch_request
    rv = self.dispatch_request()
         ^^^^^^^^^^^^^^^^^^^^^^^
  File "C:\VSCode\microblog\venv\Lib\site-packages\flask\app.py", line 1799, in dispatch_request
    return self.ensure_sync(self.view_functions[rule.endpoint])(**view_args)
           ^^^^^^^^^^^^^^^^^^^^^^^^^^^^^^^^^^^^^^^^^^^^^^^^^^^^^^^^^^^^^^^^^
  File "C:\VSCode\microblog\venv\Lib\site-packages\flask_login\utils.py", line 290, in decorated_view
    return current_app.ensure_sync(func)(*args, **kwargs)
           ^^^^^^^^^^^^^^^^^^^^^^^^^^^^^^^^^^^^^^^^^^^^^^
  File "C:\VSCode\microblog\app\routes.py", line 134, in explore
    posts = Post.query.order_by(Post.timestamp.desc()).paginate(page=page, per_page=app.config['POST_PER_PAGE'], error_out=False)
                                                                                    ~~~~~~~~~~^^^^^^^^^^^^^^^^^
KeyError: 'POST_PER_PAGE'
2023-04-19 12:22:13,291 INFO: Microblog startup [in C:\VSCode\microblog\app\__init__.py:43]
2023-04-19 12:52:13,332 INFO: Microblog startup [in C:\VSCode\microblog\app\__init__.py:43]
2023-04-19 13:01:54,304 INFO: Microblog startup [in C:\VSCode\microblog\app\__init__.py:43]
2023-04-19 13:02:18,779 INFO: Microblog startup [in C:\VSCode\microblog\app\__init__.py:43]
2023-04-19 13:04:08,607 INFO: Microblog startup [in C:\VSCode\microblog\app\__init__.py:43]
2023-04-19 13:23:49,202 INFO: Microblog startup [in C:\VSCode\microblog\app\__init__.py:45]
2023-04-19 13:33:59,183 INFO: Microblog startup [in C:\VSCode\microblog\app\__init__.py:45]
2023-04-21 16:06:06,704 INFO: Microblog startup [in C:\VSCode\microblog\app\__init__.py:45]
2023-04-21 16:12:42,737 INFO: Microblog startup [in C:\VSCode\microblog\app\__init__.py:45]
2023-04-21 16:14:36,966 INFO: Microblog startup [in C:\VSCode\microblog\app\__init__.py:45]
2023-04-21 16:15:32,561 INFO: Microblog startup [in C:\VSCode\microblog\app\__init__.py:45]
2023-04-21 17:12:28,924 INFO: Microblog startup [in C:\VSCode\microblog\app\__init__.py:45]
2023-04-21 17:13:47,077 ERROR: Exception on /reset_password_request [POST] [in C:\VSCode\microblog\venv\Lib\site-packages\flask\app.py:1744]
Traceback (most recent call last):
  File "C:\VSCode\microblog\venv\Lib\site-packages\flask\app.py", line 2528, in wsgi_app
    response = self.full_dispatch_request()
               ^^^^^^^^^^^^^^^^^^^^^^^^^^^^
  File "C:\VSCode\microblog\venv\Lib\site-packages\flask\app.py", line 1825, in full_dispatch_request
    rv = self.handle_user_exception(e)
         ^^^^^^^^^^^^^^^^^^^^^^^^^^^^^
  File "C:\VSCode\microblog\venv\Lib\site-packages\flask\app.py", line 1823, in full_dispatch_request
    rv = self.dispatch_request()
         ^^^^^^^^^^^^^^^^^^^^^^^
  File "C:\VSCode\microblog\venv\Lib\site-packages\flask\app.py", line 1799, in dispatch_request
    return self.ensure_sync(self.view_functions[rule.endpoint])(**view_args)
           ^^^^^^^^^^^^^^^^^^^^^^^^^^^^^^^^^^^^^^^^^^^^^^^^^^^^^^^^^^^^^^^^^
  File "C:\VSCode\microblog\app\routes.py", line 157, in reset_password_request
    send_password_reset_email(user)
  File "C:\VSCode\microblog\app\email.py", line 14, in send_password_reset_email
    send_email('[microblog] Reset Your Password', sender=app.config['ADMINS'][0], recipients=[user.email], text_body=render_template('email/reset_password.txt', user=user, token=token),
  File "C:\VSCode\microblog\app\email.py", line 10, in send_email
    mail.send(msg)
  File "C:\VSCode\microblog\venv\Lib\site-packages\flask_mail.py", line 491, in send
    with self.connect() as connection:
  File "C:\VSCode\microblog\venv\Lib\site-packages\flask_mail.py", line 144, in __enter__
    self.host = self.configure_host()
                ^^^^^^^^^^^^^^^^^^^^^
  File "C:\VSCode\microblog\venv\Lib\site-packages\flask_mail.py", line 158, in configure_host
    host = smtplib.SMTP(self.mail.server, self.mail.port)
           ^^^^^^^^^^^^^^^^^^^^^^^^^^^^^^^^^^^^^^^^^^^^^^
  File "C:\Users\Sean Lovins\AppData\Local\Programs\Python\Python311\Lib\smtplib.py", line 255, in __init__
    (code, msg) = self.connect(host, port)
                  ^^^^^^^^^^^^^^^^^^^^^^^^
  File "C:\Users\Sean Lovins\AppData\Local\Programs\Python\Python311\Lib\smtplib.py", line 341, in connect
    self.sock = self._get_socket(host, port, self.timeout)
                ^^^^^^^^^^^^^^^^^^^^^^^^^^^^^^^^^^^^^^^^^^
  File "C:\Users\Sean Lovins\AppData\Local\Programs\Python\Python311\Lib\smtplib.py", line 312, in _get_socket
    return socket.create_connection((host, port), timeout,
           ^^^^^^^^^^^^^^^^^^^^^^^^^^^^^^^^^^^^^^^^^^^^^^^
  File "C:\Users\Sean Lovins\AppData\Local\Programs\Python\Python311\Lib\socket.py", line 851, in create_connection
    raise exceptions[0]
  File "C:\Users\Sean Lovins\AppData\Local\Programs\Python\Python311\Lib\socket.py", line 836, in create_connection
    sock.connect(sa)
ConnectionRefusedError: [WinError 10061] No connection could be made because the target machine actively refused it
